#VRML_SIM R2022b utf8

EXTERNPROTO "https://raw.githubusercontent.com/cyberbotics/webots/R2022b/projects/objects/backgrounds/protos/TexturedBackground.proto"
EXTERNPROTO "https://raw.githubusercontent.com/cyberbotics/webots/R2022b/projects/objects/backgrounds/protos/TexturedBackgroundLight.proto"
EXTERNPROTO "https://raw.githubusercontent.com/cyberbotics/webots/R2022b/projects/objects/floors/protos/CircleArena.proto"
EXTERNPROTO "https://raw.githubusercontent.com/cyberbotics/webots/R2023b/projects/objects/geometries/protos/Extrusion.proto"

WorldInfo {
}
Viewpoint {
  orientation -0.473 0.469 0.746 1.87
  position -0.0492 -2.0 4.12
  #follow "my_robot"
}
TexturedBackground {
}
TexturedBackgroundLight {
}

CircleArena {
}

Solid {
  translation -0.4 0.2 0
  children [
    Shape {
      appearance PBRAppearance {
        baseColor 0.6 0.3 0.1
        roughness 1
        metalness 0
      }
      geometry Extrusion {
        crossSection [
          -0.08 0.08, 0.08 0.08, 0.08 -0.08, -0.08 -0.08, -0.08 0.08
        ]
        spine [
          0 0 0.08, 0 0.2 0.08, 0.2 0.4 0.08, 0.4 0.4 0.08,
          0.6 0.4 0.08, 0.8 0.2 0.08, 0.8 0 0.08,
          0.8 -0.2 0.08, 0.4 -0.4 0.08, 0.4 -0.6 0.08,
          0.4 -0.9 0.08,
        ]
        ccw TRUE
      }
    }
  ]
  name "question mark"
  boundingObject Extrusion {
    crossSection [
      -0.08 0.08, 0.08 0.08, 0.08 -0.08, -0.08 -0.08, -0.08 0.08
    ]
    spine [
      0 0 0.08, 0 0.2 0.08, 0.2 0.4 0.08, 0.4 0.4 0.08,
      0.6 0.4 0.08, 0.8 0.2 0.08, 0.8 0 0.08,
      0.8 -0.2 0.08, 0.4 -0.4 0.08, 0.4 -0.6 0.08,
      0.4 -0.9 0.08,
    ]
    ccw TRUE
  }
}

Robot {
  rotation 0 0 1 3.14
  translation -0.05 0.4 0.05

  children [
    HingeJoint {
      jointParameters HingeJointParameters {
        axis 0 1 0
        anchor 0 0 0.025
      }
      device [
        RotationalMotor {
          name "left wheel motor"
        }
      ]
      endPoint Solid {
        translation 0 0.045 0.025
        children [
          DEF WHEEL Transform {
            rotation 1 0 0 1.5707996938995747
            children [
              Shape {
                appearance PBRAppearance {
                  baseColor 1 0 0
                  roughness 1
                  metalness 0
                }
                geometry Cylinder {
                  height 0.01
                  radius 0.025
                }
              }
            ]
          }
        ]
        name "left wheel"
        boundingObject USE WHEEL
        physics Physics {
        }
      }
    }
    HingeJoint {
      jointParameters HingeJointParameters {
        axis 0 1 0
        anchor 0 0 0.025
      }
      device [
        RotationalMotor {
          name "right wheel motor"
        }
      ]
      endPoint Solid {
        translation 0 -0.045 0.025
        children [
          USE WHEEL
        ]
        name "right wheel"
        boundingObject USE WHEEL
        physics Physics {
        }
      }
    }
    Transform {
      translation 0 0 0.0415
      children [
        Shape {
          appearance PBRAppearance {
            baseColor 0 0 1
            roughness 1
            metalness 0
          }
          geometry DEF BODY Cylinder {
            height 0.08
            radius 0.045
          }
        }
      ]
    }
    DistanceSensor {
      translation 0.042 0.02 0.063
      rotation 0 0 1 0.5236003061004253
      children [
        DEF SENSOR Transform {
          rotation 0 1 0 1.5708
          children [
            Shape {
              appearance PBRAppearance {
                baseColor 1 1 0
                roughness 1
                metalness 0
              }
              geometry Cylinder {
                height 0.004
                radius 0.008
              }
            }
          ]
        }
      ]
      name "ds0"
      lookupTable [
        0 1020 0
        0.05 1020 0
        0.15 0 0
      ]
      numberOfRays 2
      aperture 1
    }
    DistanceSensor {
      translation 0.042 -0.02 0.063
      rotation 0 0 1 -0.5235996938995747
      children [
        USE SENSOR
      ]
      name "ds1"
      lookupTable [
        0 1020 0
        0.05 1020 0
        0.15 0 0
      ]
      numberOfRays 2
      aperture 1
    }
  ]
  boundingObject Transform {
    translation 0 0 0.0415
    children [
      USE BODY
    ]
  }
  physics Physics {
  }
  controller "<extern>"
  name "robot1"
}

Robot {
  rotation 0 0 1 0.524
  translation 0.02 -0.82 0.05
  children [
    HingeJoint {
      jointParameters HingeJointParameters {
        axis 0 1 0
        anchor 0 0 0.025
      }
      device [
        RotationalMotor {
          name "left wheel motor"
        }
      ]
      endPoint Solid {
        translation 0 0.045 0.025
        children [
          DEF WHEEL Transform {
            rotation 1 0 0 1.5707996938995747
            children [
              Shape {
                appearance PBRAppearance {
                  baseColor 1 0 0
                  roughness 1
                  metalness 0
                }
                geometry Cylinder {
                  height 0.01
                  radius 0.025
                }
              }
            ]
          }
        ]
        name "left wheel"
        boundingObject USE WHEEL
        physics Physics {
        }
      }
    }
    HingeJoint {
      jointParameters HingeJointParameters {
        axis 0 1 0
        anchor 0 0 0.025
      }
      device [
        RotationalMotor {
          name "right wheel motor"
        }
      ]
      endPoint Solid {
        translation 0 -0.045 0.025
        children [
          USE WHEEL
        ]
        name "right wheel"
        boundingObject USE WHEEL
        physics Physics {
        }
      }
    }
    Transform {
      translation 0 0 0.0415
      children [
        Shape {
          appearance PBRAppearance {
            baseColor 0 1 0  # Verde para diferenciar
            roughness 1
            metalness 0
          }
          geometry DEF BODY Cylinder {
            height 0.08
            radius 0.045
          }
        }
      ]
    }
    DistanceSensor {
      translation 0.042 0.02 0.063
      rotation 0 0 1 0.5236003061004253
      children [
        DEF SENSOR Transform {
          rotation 0 1 0 1.5708
          children [
            Shape {
              appearance PBRAppearance {
                baseColor 1 1 0
                roughness 1
                metalness 0
              }
              geometry Cylinder {
                height 0.004
                radius 0.008
              }
            }
          ]
        }
      ]
      name "ds0" 
      lookupTable [
        0 1020 0
        0.05 1020 0
        0.35 0 0
      ]
      numberOfRays 2
      aperture 1
    }
    DistanceSensor {
      translation 0.042 -0.02 0.063
      rotation 0 0 1 -0.5235996938995747
      children [
        USE SENSOR
      ]
      name "ds1" 
      lookupTable [
        0 1020 0
        0.05 1020 0
        0.35 0 0
      ]
      numberOfRays 2
      aperture 1
    }
  ]
  boundingObject Transform {
    translation 0 0 0.0415
    children [
      USE BODY
    ]
  }
  physics Physics {
  }
  controller "<extern>"
  name "robot2" 
}